Workbook

Sheet CUSTOMERS
A1: customer_id | B1: gender | C1: age_group
A2: 1 | B2: =IF(RANDBETWEEN(0,1)=0,"Male","Female") -> Male | C2: =CHOOSE(RANDBETWEEN(1,4),"18-25","26-35","36-45","46+") -> 26-35
A3: 2 | B3: =IF(RANDBETWEEN(0,1)=0,"Male","Female") -> Male | C3: =CHOOSE(RANDBETWEEN(1,4),"18-25","26-35","36-45","46+") -> 26-35
A4: 3 | B4: =IF(RANDBETWEEN(0,1)=0,"Male","Female") -> Male | C4: =CHOOSE(RANDBETWEEN(1,4),"18-25","26-35","36-45","46+") -> 36-45
A5: 4 | B5: =IF(RANDBETWEEN(0,1)=0,"Male","Female") -> Female | C5: =CHOOSE(RANDBETWEEN(1,4),"18-25","26-35","36-45","46+") -> 46+
A6: 5 | B6: =IF(RANDBETWEEN(0,1)=0,"Male","Female") -> Female | C6: =CHOOSE(RANDBETWEEN(1,4),"18-25","26-35","36-45","46+") -> 46+
A7: 6 | B7: =IF(RANDBETWEEN(0,1)=0,"Male","Female") -> Female | C7: =CHOOSE(RANDBETWEEN(1,4),"18-25","26-35","36-45","46+") -> 26-35
A8: 7 | B8: =IF(RANDBETWEEN(0,1)=0,"Male","Female") -> Male | C8: =CHOOSE(RANDBETWEEN(1,4),"18-25","26-35","36-45","46+") -> 18-25
A9: 8 | B9: =IF(RANDBETWEEN(0,1)=0,"Male","Female") -> Male | C9: =CHOOSE(RANDBETWEEN(1,4),"18-25","26-35","36-45","46+") -> 26-35
A10: 9 | B10: =IF(RANDBETWEEN(0,1)=0,"Male","Female") -> Female | C10: =CHOOSE(RANDBETWEEN(1,4),"18-25","26-35","36-45","46+") -> 26-35
A11: 10 | B11: =IF(RANDBETWEEN(0,1)=0,"Male","Female") -> Male | C11: =CHOOSE(RANDBETWEEN(1,4),"18-25","26-35","36-45","46+") -> 18-25
A12: 11 | B12: =IF(RANDBETWEEN(0,1)=0,"Male","Female") -> Male | C12: =CHOOSE(RANDBETWEEN(1,4),"18-25","26-35","36-45","46+") -> 26-35
A13: 12 | B13: =IF(RANDBETWEEN(0,1)=0,"Male","Female") -> Female | C13: =CHOOSE(RANDBETWEEN(1,4),"18-25","26-35","36-45","46+") -> 18-25
... A101: 100 | B101: =IF(RANDBETWEEN(0,1)=0,"Male","Female") -> Male | C101: =CHOOSE(RANDBETWEEN(1,4),"18-25","26-35","36-45","46+") -> 36-45

Sheet ORDERS
A1: order_id | B1: customer_id | C1: store_id | D1: order_date
A2: 1 | B2: 27 | C2: 2 | D2: 45743
A3: 2 | B3: 40 | C3: 1 | D3: 45835
A4: 3 | B4: 57 | C4: 1 | D4: 45957
A5: 4 | B5: 48 | C5: 3 | D5: 45731
A6: 5 | B6: 67 | C6: 4 | D6: 45934
A7: 6 | B7: 88 | C7: 4 | D7: 45981
A8: 7 | B8: 60 | C8: 4 | D8: 45815
A9: 8 | B9: 4 | C9: 9 | D9: 45927
A10: 9 | B10: 50 | C10: 3 | D10: 45740
A11: 10 | B11: 16 | C11: 5 | D11: 45815
A12: 11 | B12: 74 | C12: 7 | D12: 45878
A13: 12 | B13: 69 | C13: 8 | D13: 45922
... A201: 200 | B201: 16 | C201: 4 | D201: 45995

Sheet PRODUCTS
A1: product _id | B1: product_name | C1: category | D1: price | E1: cost
A2: 1 | B2: T-shirt | C2: Men | D2: 499 | E2: 250
A3: 2 | B3: Jeans | C3: Men | D3: 999 | E3: 600
A4: 3 | B4: Shirt | C4: Men | D4: 799 | E4: 450
A5: 4 | B5: Hoodie | C5: Men | D5: 1199 | E5: 700
A6: 5 | B6: Shorts | C6: Men | D6: 399 | E6: 200
A7: 6 | B7: Track Pants | C7: Men | D7: 699 | E7: 350
A8: 7 | B8: Jacket | C8: Men | D8: 1499 | E8: 900
A9: 8 | B9: Polo T-shirt | C9: Men | D9: 599 | E9: 300
A10: 9 | B10: Formal Shirt | C10: Men | D10: 899 | E10: 500
A11: 10 | B11: Denim Jacket | C11: Men | D11: 1599 | E11: 950
A12: 11 | B12: Kurti | C12: Women | D12: 799 | E12: 400
A13: 12 | B13: Dress | C13: Women | D13: 1199 | E13: 700
... A51: 50 | B51: Backpack | C51: Kids | D51: 999 | E51: 600

Sheet ORDER DETAILS
A1: order_id | B1: product_id | C1: quantity | D1: Revenue | E1: Profit | F1: category | G1: order_date | I1: Row Labels | J1: Sum of Revenue
A2: 28 | B2: 23 | C2: 4 | D2: =VLOOKUP(B2,PRODUCTS!A:E,4,FALSE)*C2 -> 2396 | E2: =(VLOOKUP(B2,PRODUCTS!A:E,4,FALSE) - VLOOKUP(B2,PRODUCTS!A:E,5,FALSE)) * C2 -> 1196 | F2: Men | G2: 45743 | I2: Kids | J2: 45005
A3: 37 | B3: 2 | C3: 2 | D3: =VLOOKUP(B3,PRODUCTS!A:E,4,FALSE)*C3 -> 1998 | E3: =(VLOOKUP(B3,PRODUCTS!A:E,4,FALSE) - VLOOKUP(B3,PRODUCTS!A:E,5,FALSE)) * C3 -> 798 | F3: Men | G3: 45835 | I3: Men | J3: 31153
A4: 154 | B4: 9 | C4: 2 | D4: =VLOOKUP(B4,PRODUCTS!A:E,4,FALSE)*C4 -> 1798 | E4: =(VLOOKUP(B4,PRODUCTS!A:E,4,FALSE) - VLOOKUP(B4,PRODUCTS!A:E,5,FALSE)) * C4 -> 798 | F4: Men | G4: 45957 | I4: Women | J4: 35750
A5: 179 | B5: 21 | C5: 1 | D5: =VLOOKUP(B5,PRODUCTS!A:E,4,FALSE)*C5 -> 299 | E5: =(VLOOKUP(B5,PRODUCTS!A:E,4,FALSE) - VLOOKUP(B5,PRODUCTS!A:E,5,FALSE)) * C5 -> 149 | F5: Men | G5: 45731 | I5: Grand Total | J5: 111908
A6: 4 | B6: 23 | C6: 3 | D6: =VLOOKUP(B6,PRODUCTS!A:E,4,FALSE)*C6 -> 1797 | E6: =(VLOOKUP(B6,PRODUCTS!A:E,4,FALSE) - VLOOKUP(B6,PRODUCTS!A:E,5,FALSE)) * C6 -> 897 | F6: Men | G6: 45934
A7: 105 | B7: 8 | C7: 3 | D7: =VLOOKUP(B7,PRODUCTS!A:E,4,FALSE)*C7 -> 1797 | E7: =(VLOOKUP(B7,PRODUCTS!A:E,4,FALSE) - VLOOKUP(B7,PRODUCTS!A:E,5,FALSE)) * C7 -> 897 | F7: Men | G7: 45981
A8: 125 | B8: 25 | C8: 4 | D8: =VLOOKUP(B8,PRODUCTS!A:E,4,FALSE)*C8 -> 3196 | E8: =(VLOOKUP(B8,PRODUCTS!A:E,4,FALSE) - VLOOKUP(B8,PRODUCTS!A:E,5,FALSE)) * C8 -> 1596 | F8: Men | G8: 45815
A9: 165 | B9: 4 | C9: 3 | D9: =VLOOKUP(B9,PRODUCTS!A:E,4,FALSE)*C9 -> 3597 | E9: =(VLOOKUP(B9,PRODUCTS!A:E,4,FALSE) - VLOOKUP(B9,PRODUCTS!A:E,5,FALSE)) * C9 -> 1497 | F9: Men | G9: 45927
A10: 108 | B10: 17 | C10: 1 | D10: =VLOOKUP(B10,PRODUCTS!A:E,4,FALSE)*C10 -> 399 | E10: =(VLOOKUP(B10,PRODUCTS!A:E,4,FALSE) - VLOOKUP(B10,PRODUCTS!A:E,5,FALSE)) * C10 -> 199 | F10: Men | G10: 45740
A11: 189 | B11: 2 | C11: 3 | D11: =VLOOKUP(B11,PRODUCTS!A:E,4,FALSE)*C11 -> 2997 | E11: =(VLOOKUP(B11,PRODUCTS!A:E,4,FALSE) - VLOOKUP(B11,PRODUCTS!A:E,5,FALSE)) * C11 -> 1197 | F11: Men | G11: 45815
A12: 179 | B12: 17 | C12: 1 | D12: =VLOOKUP(B12,PRODUCTS!A:E,4,FALSE)*C12 -> 399 | E12: =(VLOOKUP(B12,PRODUCTS!A:E,4,FALSE) - VLOOKUP(B12,PRODUCTS!A:E,5,FALSE)) * C12 -> 199 | F12: Women | G12: 45878
A13: 72 | B13: 18 | C13: 1 | D13: =VLOOKUP(B13,PRODUCTS!A:E,4,FALSE)*C13 -> 799 | E13: =(VLOOKUP(B13,PRODUCTS!A:E,4,FALSE) - VLOOKUP(B13,PRODUCTS!A:E,5,FALSE)) * C13 -> 349 | F13: Women | G13: 45922
A14: 137 | B14: 13 | C14: 5 | D14: =VLOOKUP(B14,PRODUCTS!A:E,4,FALSE)*C14 -> 2495 | E14: =(VLOOKUP(B14,PRODUCTS!A:E,4,FALSE) - VLOOKUP(B14,PRODUCTS!A:E,5,FALSE)) * C14 -> 1245 | F14: Women | G14: 45728
A15: 21 | B15: 1 | C15: 3 | D15: =VLOOKUP(B15,PRODUCTS!A:E,4,FALSE)*C15 -> 1497 | E15: =(VLOOKUP(B15,PRODUCTS!A:E,4,FALSE) - VLOOKUP(B15,PRODUCTS!A:E,5,FALSE)) * C15 -> 747 | F15: Women | G15: 45963
A16: 116 | B16: 22 | C16: 4 | D16: =VLOOKUP(B16,PRODUCTS!A:E,4,FALSE)*C16 -> 1396 | E16: =(VLOOKUP(B16,PRODUCTS!A:E,4,FALSE) - VLOOKUP(B16,PRODUCTS!A:E,5,FALSE)) * C16 -> 676 | F16: Women | G16: 45774 | I16: Row Labels | J16: Sum of Revenue
A17: 114 | B17: 1 | C17: 5 | D17: =VLOOKUP(B17,PRODUCTS!A:E,4,FALSE)*C17 -> 2495 | E17: =(VLOOKUP(B17,PRODUCTS!A:E,4,FALSE) - VLOOKUP(B17,PRODUCTS!A:E,5,FALSE)) * C17 -> 1245 | F17: Women | G17: 45712 | I17: Jan | J17: 45347
A18: 36 | B18: 1 | C18: 5 | D18: =VLOOKUP(B18,PRODUCTS!A:E,4,FALSE)*C18 -> 2495 | E18: =(VLOOKUP(B18,PRODUCTS!A:E,4,FALSE) - VLOOKUP(B18,PRODUCTS!A:E,5,FALSE)) * C18 -> 1245 | F18: Women | G18: 45781 | I18: Feb | J18: 35706
A19: 25 | B19: 16 | C19: 2 | D19: =VLOOKUP(B19,PRODUCTS!A:E,4,FALSE)*C19 -> 1198 | E19: =(VLOOKUP(B19,PRODUCTS!A:E,4,FALSE) - VLOOKUP(B19,PRODUCTS!A:E,5,FALSE)) * C19 -> 598 | F19: Women | G19: 45943 | I19: Mar | J19: 49084
A20: 96 | B20: 2 | C20: 4 | D20: =VLOOKUP(B20,PRODUCTS!A:E,4,FALSE)*C20 -> 3996 | E20: =(VLOOKUP(B20,PRODUCTS!A:E,4,FALSE) - VLOOKUP(B20,PRODUCTS!A:E,5,FALSE)) * C20 -> 1596 | F20: Women | G20: 45906 | I20: Apr | J20: 35840
A21: 85 | B21: 16 | C21: 2 | D21: =VLOOKUP(B21,PRODUCTS!A:E,4,FALSE)*C21 -> 1198 | E21: =(VLOOKUP(B21,PRODUCTS!A:E,4,FALSE) - VLOOKUP(B21,PRODUCTS!A:E,5,FALSE)) * C21 -> 598 | F21: Women | G21: 45795 | I21: May | J21: 36601
A22: 179 | B22: 20 | C22: 3 | D22: =VLOOKUP(B22,PRODUCTS!A:E,4,FALSE)*C22 -> 4197 | E22: =(VLOOKUP(B22,PRODUCTS!A:E,4,FALSE) - VLOOKUP(B22,PRODUCTS!A:E,5,FALSE)) * C22 -> 1647 | F22: Kids | G22: 45876 | I22: Jun | J22: 32759
A23: 79 | B23: 11 | C23: 2 | D23: =VLOOKUP(B23,PRODUCTS!A:E,4,FALSE)*C23 -> 1598 | E23: =(VLOOKUP(B23,PRODUCTS!A:E,4,FALSE) - VLOOKUP(B23,PRODUCTS!A:E,5,FALSE)) * C23 -> 798 | F23: Kids | G23: 46012 | I23: Jul | J23: 29113
A24: 200 | B24: 4 | C24: 3 | D24: =VLOOKUP(B24,PRODUCTS!A:E,4,FALSE)*C24 -> 3597 | E24: =(VLOOKUP(B24,PRODUCTS!A:E,4,FALSE) - VLOOKUP(B24,PRODUCTS!A:E,5,FALSE)) * C24 -> 1497 | F24: Kids | G24: 45844 | I24: Aug | J24: 51239
A25: 173 | B25: 24 | C25: 4 | D25: =VLOOKUP(B25,PRODUCTS!A:E,4,FALSE)*C25 -> 2796 | E25: =(VLOOKUP(B25,PRODUCTS!A:E,4,FALSE) - VLOOKUP(B25,PRODUCTS!A:E,5,FALSE)) * C25 -> 1396 | F25: Kids | G25: 45662 | I25: Sep | J25: 68731
A26: 16 | B26: 25 | C26: 1 | D26: =VLOOKUP(B26,PRODUCTS!A:E,4,FALSE)*C26 -> 799 | E26: =(VLOOKUP(B26,PRODUCTS!A:E,4,FALSE) - VLOOKUP(B26,PRODUCTS!A:E,5,FALSE)) * C26 -> 399 | F26: Kids | G26: 45818 | I26: Oct | J26: 61626
A27: 162 | B27: 22 | C27: 3 | D27: =VLOOKUP(B27,PRODUCTS!A:E,4,FALSE)*C27 -> 1047 | E27: =(VLOOKUP(B27,PRODUCTS!A:E,4,FALSE) - VLOOKUP(B27,PRODUCTS!A:E,5,FALSE)) * C27 -> 507 | F27: Kids | G27: 45985 | I27: Nov | J27: 30811
A28: 16 | B28: 16 | C28: 1 | D28: =VLOOKUP(B28,PRODUCTS!A:E,4,FALSE)*C28 -> 599 | E28: =(VLOOKUP(B28,PRODUCTS!A:E,4,FALSE) - VLOOKUP(B28,PRODUCTS!A:E,5,FALSE)) * C28 -> 299 | F28: Kids | G28: 45833 | I28: Dec | J28: 35462
A29: 186 | B29: 24 | C29: 1 | D29: =VLOOKUP(B29,PRODUCTS!A:E,4,FALSE)*C29 -> 699 | E29: =(VLOOKUP(B29,PRODUCTS!A:E,4,FALSE) - VLOOKUP(B29,PRODUCTS!A:E,5,FALSE)) * C29 -> 349 | F29: Kids | G29: 45935 | I29: Grand Total | J29: 512319
A30: 54 | B30: 14 | C30: 1 | D30: =VLOOKUP(B30,PRODUCTS!A:E,4,FALSE)*C30 -> 699 | E30: =(VLOOKUP(B30,PRODUCTS!A:E,4,FALSE) - VLOOKUP(B30,PRODUCTS!A:E,5,FALSE)) * C30 -> 349 | F30: Kids | G30: 45801
A31: 4 | B31: 19 | C31: 5 | D31: =VLOOKUP(B31,PRODUCTS!A:E,4,FALSE)*C31 -> 6495 | E31: =(VLOOKUP(B31,PRODUCTS!A:E,4,FALSE) - VLOOKUP(B31,PRODUCTS!A:E,5,FALSE)) * C31 -> 2495 | F31: Kids | G31: 45710
A32: 167 | B32: 14 | C32: 1 | D32: =VLOOKUP(B32,PRODUCTS!A:E,4,FALSE)*C32 -> 699 | E32: =(VLOOKUP(B32,PRODUCTS!A:E,4,FALSE) - VLOOKUP(B32,PRODUCTS!A:E,5,FALSE)) * C32 -> 349 | F32: Men | G32: 45797
A33: 125 | B33: 21 | C33: 3 | D33: =VLOOKUP(B33,PRODUCTS!A:E,4,FALSE)*C33 -> 897 | E33: =(VLOOKUP(B33,PRODUCTS!A:E,4,FALSE) - VLOOKUP(B33,PRODUCTS!A:E,5,FALSE)) * C33 -> 447 | F33: Men | G33: 45852
A34: 23 | B34: 1 | C34: 5 | D34: =VLOOKUP(B34,PRODUCTS!A:E,4,FALSE)*C34 -> 2495 | E34: =(VLOOKUP(B34,PRODUCTS!A:E,4,FALSE) - VLOOKUP(B34,PRODUCTS!A:E,5,FALSE)) * C34 -> 1245 | F34: Men | G34: 45720
A35: 17 | B35: 16 | C35: 4 | D35: =VLOOKUP(B35,PRODUCTS!A:E,4,FALSE)*C35 -> 2396 | E35: =(VLOOKUP(B35,PRODUCTS!A:E,4,FALSE) - VLOOKUP(B35,PRODUCTS!A:E,5,FALSE)) * C35 -> 1196 | F35: Men | G35: 45909
A36: 59 | B36: 18 | C36: 1 | D36: =VLOOKUP(B36,PRODUCTS!A:E,4,FALSE)*C36 -> 799 | E36: =(VLOOKUP(B36,PRODUCTS!A:E,4,FALSE) - VLOOKUP(B36,PRODUCTS!A:E,5,FALSE)) * C36 -> 349 | F36: Men | G36: 45671
A37: 109 | B37: 12 | C37: 2 | D37: =VLOOKUP(B37,PRODUCTS!A:E,4,FALSE)*C37 -> 2398 | E37: =(VLOOKUP(B37,PRODUCTS!A:E,4,FALSE) - VLOOKUP(B37,PRODUCTS!A:E,5,FALSE)) * C37 -> 998 | F37: Women | G37: 45778
A38: 23 | B38: 15 | C38: 2 | D38: =VLOOKUP(B38,PRODUCTS!A:E,4,FALSE)*C38 -> 2998 | E38: =(VLOOKUP(B38,PRODUCTS!A:E,4,FALSE) - VLOOKUP(B38,PRODUCTS!A:E,5,FALSE)) * C38 -> 1198 | F38: Women | G38: 46013
A39: 85 | B39: 10 | C39: 1 | D39: =VLOOKUP(B39,PRODUCTS!A:E,4,FALSE)*C39 -> 1599 | E39: =(VLOOKUP(B39,PRODUCTS!A:E,4,FALSE) - VLOOKUP(B39,PRODUCTS!A:E,5,FALSE)) * C39 -> 649 | F39: Women | G39: 46019
A40: 24 | B40: 18 | C40: 3 | D40: =VLOOKUP(B40,PRODUCTS!A:E,4,FALSE)*C40 -> 2397 | E40: =(VLOOKUP(B40,PRODUCTS!A:E,4,FALSE) - VLOOKUP(B40,PRODUCTS!A:E,5,FALSE)) * C40 -> 1047 | F40: Women | G40: 45809
...

Sheet STORES
A1: store_id | B1: city | C1: region
A2: 1 | B2: Delhi | C2: North
A3: 2 | B3: Mumbai | C3: West
A4: 3 | B4: Jaipur | C4: North
A5: 4 | B5: Bangalore | C5: South
A6: 5 | B6: Chennai | C6: South
A7: 6 | B7: Kolkata | C7: East
A8: 7 | B8: Hyderabad | C8: South
A9: 8 | B9: Pune | C9: West
A10: 9 | B10: Ahmedabad | C10: West
A11: 10 | B11: Lucknow | C11: North
A12: 11 | B12: Chandigarh | C12: North
A13: 12 | B13: Goa | C13: West

Sheet COMBINE
A1: customer_id | B1: gender | C1: age_group | D1: order_id | E1: customer_id | F1: store_id | G1: order_date | H1: product _id | I1: product_name | J1: category | K1: price | L1: cost | M1: order_id | N1: product_id | O1: quantity | P1: store_id | Q1: city | R1: region
A2: 1 | B2: =IF(RANDBETWEEN(0,1)=0,"Male","Female") -> Male | C2: =CHOOSE(RANDBETWEEN(1,4),"18-25","26-35","36-45","46+") -> 36-45 | D2: 1 | E2: 27 | F2: 2 | G2: 45743 | H2: 1 | I2: T-shirt | J2: Men | K2: 499 | L2: 250 | M2: 28 | N2: 23 | O2: 4 | P2: 1 | Q2: Delhi | R2: North
A3: 2 | B3: =IF(RANDBETWEEN(0,1)=0,"Male","Female") -> Female | C3: =CHOOSE(RANDBETWEEN(1,4),"18-25","26-35","36-45","46+") -> 18-25 | D3: 2 | E3: 40 | F3: 1 | G3: 45835 | H3: 2 | I3: Jeans | J3: Men | K3: 999 | L3: 600 | M3: 37 | N3: 2 | O3: 2 | P3: 2 | Q3: Mumbai | R3: West
A4: 3 | B4: =IF(RANDBETWEEN(0,1)=0,"Male","Female") -> Female | C4: =CHOOSE(RANDBETWEEN(1,4),"18-25","26-35","36-45","46+") -> 18-25 | D4: 3 | E4: 57 | F4: 1 | G4: 45957 | H4: 3 | I4: Shirt | J4: Men | K4: 799 | L4: 450 | M4: 154 | N4: 9 | O4: 2 | P4: 3 | Q4: Jaipur | R4: North
A5: 4 | B5: =IF(RANDBETWEEN(0,1)=0,"Male","Female") -> Male | C5: =CHOOSE(RANDBETWEEN(1,4),"18-25","26-35","36-45","46+") -> 26-35 | D5: 4 | E5: 48 | F5: 3 | G5: 45731 | H5: 4 | I5: Hoodie | J5: Men | K5: 1199 | L5: 700 | M5: 179 | N5: 21 | O5: 1 | P5: 4 | Q5: Bangalore | R5: South
A6: 5 | B6: =IF(RANDBETWEEN(0,1)=0,"Male","Female") -> Female | C6: =CHOOSE(RANDBETWEEN(1,4),"18-25","26-35","36-45","46+") -> 36-45 | D6: 5 | E6: 67 | F6: 4 | G6: 45934 | H6: 5 | I6: Shorts | J6: Men | K6: 399 | L6: 200 | M6: 4 | N6: 23 | O6: 3 | P6: 5 | Q6: Chennai | R6: South
A7: 6 | B7: =IF(RANDBETWEEN(0,1)=0,"Male","Female") -> Male | C7: =CHOOSE(RANDBETWEEN(1,4),"18-25","26-35","36-45","46+") -> 18-25 | D7: 6 | E7: 88 | F7: 4 | G7: 45981 | H7: 6 | I7: Track Pants | J7: Men | K7: 699 | L7: 350 | M7: 105 | N7: 8 | O7: 3 | P7: 6 | Q7: Kolkata | R7: East
A8: 7 | B8: =IF(RANDBETWEEN(0,1)=0,"Male","Female") -> Male | C8: =CHOOSE(RANDBETWEEN(1,4),"18-25","26-35","36-45","46+") -> 46+ | D8: 7 | E8: 60 | F8: 4 | G8: 45815 | H8: 7 | I8: Jacket | J8: Men | K8: 1499 | L8: 900 | M8: 125 | N8: 25 | O8: 4 | P8: 7 | Q8: Hyderabad | R8: South
A9: 8 | B9: =IF(RANDBETWEEN(0,1)=0,"Male","Female") -> Male | C9: =CHOOSE(RANDBETWEEN(1,4),"18-25","26-35","36-45","46+") -> 46+ | D9: 8 | E9: 4 | F9: 9 | G9: 45927 | H9: 8 | I9: Polo T-shirt | J9: Men | K9: 599 | L9: 300 | M9: 165 | N9: 4 | O9: 3 | P9: 8 | Q9: Pune | R9: West
A10: 9 | B10: =IF(RANDBETWEEN(0,1)=0,"Male","Female") -> Female | C10: =CHOOSE(RANDBETWEEN(1,4),"18-25","26-35","36-45","46+") -> 46+ | D10: 9 | E10: 50 | F10: 3 | G10: 45740 | H10: 9 | I10: Formal Shirt | J10: Men | K10: 899 | L10: 500 | M10: 108 | N10: 17 | O10: 1 | P10: 9 | Q10: Ahmedabad | R10: West
A11: 10 | B11: =IF(RANDBETWEEN(0,1)=0,"Male","Female") -> Male | C11: =CHOOSE(RANDBETWEEN(1,4),"18-25","26-35","36-45","46+") -> 18-25 | D11: 10 | E11: 16 | F11: 5 | G11: 45815 | H11: 10 | I11: Denim Jacket | J11: Men | K11: 1599 | L11: 950 | M11: 189 | N11: 2 | O11: 3 | P11: 10 | Q11: Lucknow | R11: North
A12: 11 | B12: =IF(RANDBETWEEN(0,1)=0,"Male","Female") -> Female | C12: =CHOOSE(RANDBETWEEN(1,4),"18-25","26-35","36-45","46+") -> 18-25 | D12: 11 | E12: 74 | F12: 7 | G12: 45878 | H12: 11 | I12: Kurti | J12: Women | K12: 799 | L12: 400 | M12: 179 | N12: 17 | O12: 1
A13: 12 | B13: =IF(RANDBETWEEN(0,1)=0,"Male","Female") -> Female | C13: =CHOOSE(RANDBETWEEN(1,4),"18-25","26-35","36-45","46+") -> 26-35 | D13: 12 | E13: 69 | F13: 8 | G13: 45922 | H13: 12 | I13: Dress | J13: Women | K13: 1199 | L13: 700 | M13: 72 | N13: 18 | O13: 1
A14: 13 | B14: =IF(RANDBETWEEN(0,1)=0,"Male","Female") -> Male | C14: =CHOOSE(RANDBETWEEN(1,4),"18-25","26-35","36-45","46+") -> 36-45 | D14: 13 | E14: 34 | F14: 8 | G14: 45728 | H14: 13 | I14: Top | J14: Women | K14: 499 | L14: 250 | M14: 137 | N14: 13 | O14: 5
A15: 14 | B15: =IF(RANDBETWEEN(0,1)=0,"Male","Female") -> Female | C15: =CHOOSE(RANDBETWEEN(1,4),"18-25","26-35","36-45","46+") -> 26-35 | D15: 14 | E15: 74 | F15: 1 | G15: 45963 | H15: 14 | I15: Skirt | J15: Women | K15: 699 | L15: 350 | M15: 21 | N15: 1 | O15: 3
A16: 15 | B16: =IF(RANDBETWEEN(0,1)=0,"Male","Female") -> Female | C16: =CHOOSE(RANDBETWEEN(1,4),"18-25","26-35","36-45","46+") -> 46+ | D16: 15 | E16: 13 | F16: 2 | G16: 45774 | H16: 15 | I16: Saree | J16: Women | K16: 1499 | L16: 900 | M16: 116 | N16: 22 | O16: 4
A17: 16 | B17: =IF(RANDBETWEEN(0,1)=0,"Male","Female") -> Male | C17: =CHOOSE(RANDBETWEEN(1,4),"18-25","26-35","36-45","46+") -> 36-45 | D17: 16 | E17: 30 | F17: 2 | G17: 45712 | H17: 16 | I17: Palazzo | J17: Women | K17: 599 | L17: 300 | M17: 114 | N17: 1 | O17: 5
A18: 17 | B18: =IF(RANDBETWEEN(0,1)=0,"Male","Female") -> Female | C18: =CHOOSE(RANDBETWEEN(1,4),"18-25","26-35","36-45","46+") -> 18-25 | D18: 17 | E18: 40 | F18: 8 | G18: 45781 | H18: 17 | I18: Leggings | J18: Women | K18: 399 | L18: 200 | M18: 36 | N18: 1 | O18: 5
A19: 18 | B19: =IF(RANDBETWEEN(0,1)=0,"Male","Female") -> Male | C19: =CHOOSE(RANDBETWEEN(1,4),"18-25","26-35","36-45","46+") -> 26-35 | D19: 18 | E19: 71 | F19: 5 | G19: 45943 | H19: 18 | I19: Tunic | J19: Women | K19: 799 | L19: 450 | M19: 25 | N19: 16 | O19: 2
A20: 19 | B20: =IF(RANDBETWEEN(0,1)=0,"Male","Female") -> Female | C20: =CHOOSE(RANDBETWEEN(1,4),"18-25","26-35","36-45","46+") -> 18-25 | D20: 19 | E20: 4 | F20: 9 | G20: 45906 | H20: 19 | I20: Co-ord Set | J20: Women | K20: 1299 | L20: 800 | M20: 96 | N20: 2 | O20: 4
A21: 20 | B21: =IF(RANDBETWEEN(0,1)=0,"Male","Female") -> Male | C21: =CHOOSE(RANDBETWEEN(1,4),"18-25","26-35","36-45","46+") -> 36-45 | D21: 20 | E21: 20 | F21: 6 | G21: 45795 | H21: 20 | I21: Jumpsuit | J21: Women | K21: 1399 | L21: 850 | M21: 85 | N21: 16 | O21: 2
A22: 21 | B22: =IF(RANDBETWEEN(0,1)=0,"Male","Female") -> Female | C22: =CHOOSE(RANDBETWEEN(1,4),"18-25","26-35","36-45","46+") -> 26-35 | D22: 21 | E22: 66 | F22: 7 | G22: 45876 | H22: 21 | I22: Kids T-shirt | J22: Kids | K22: 299 | L22: 150 | M22: 179 | N22: 20 | O22: 3
A23: 22 | B23: =IF(RANDBETWEEN(0,1)=0,"Male","Female") -> Male | C23: =CHOOSE(RANDBETWEEN(1,4),"18-25","26-35","36-45","46+") -> 26-35 | D23: 22 | E23: 82 | F23: 5 | G23: 46012 | H23: 22 | I23: Kids Shorts | J23: Kids | K23: 349 | L23: 180 | M23: 79 | N23: 11 | O23: 2
... A51: 50 | B51: =IF(RANDBETWEEN(0,1)=0,"Male","Female") -> Female | C51: =CHOOSE(RANDBETWEEN(1,4),"18-25","26-35","36-45","46+") -> 26-35 | D51: 50 | E51: 55 | F51: 2 | G51: 45848 | H51: 50 | I51: Backpack | J51: Kids | K51: 999 | L51: 600 | M51: 154 | N51: 3 | O51: 3
A52: 51 | B52: =IF(RANDBETWEEN(0,1)=0,"Male","Female") -> Male | C52: =CHOOSE(RANDBETWEEN(1,4),"18-25","26-35","36-45","46+") -> 46+ | D52: 51 | E52: 21 | F52: 3 | G52: 45778 | M52: 87 | N52: 13 | O52: 5
A53: 52 | B53: =IF(RANDBETWEEN(0,1)=0,"Male","Female") -> Female | C53: =CHOOSE(RANDBETWEEN(1,4),"18-25","26-35","36-45","46+") -> 36-45 | D53: 52 | E53: 78 | F53: 8 | G53: 45902 | M53: 9 | N53: 21 | O53: 3
A54: 53 | B54: =IF(RANDBETWEEN(0,1)=0,"Male","Female") -> Female | C54: =CHOOSE(RANDBETWEEN(1,4),"18-25","26-35","36-45","46+") -> 46+ | D54: 53 | E54: 43 | F54: 6 | G54: 46001 | M54: 68 | N54: 1 | O54: 1
A55: 54 | B55: =IF(RANDBETWEEN(0,1)=0,"Male","Female") -> Male | C55: =CHOOSE(RANDBETWEEN(1,4),"18-25","26-35","36-45","46+") -> 46+ | D55: 54 | E55: 95 | F55: 10 | G55: 45773 | M55: 65 | N55: 13 | O55: 5
A56: 55 | B56: =IF(RANDBETWEEN(0,1)=0,"Male","Female") -> Male | C56: =CHOOSE(RANDBETWEEN(1,4),"18-25","26-35","36-45","46+") -> 18-25 | D56: 55 | E56: 34 | F56: 9 | G56: 45896 | M56: 74 | N56: 14 | O56: 3
A57: 56 | B57: =IF(RANDBETWEEN(0,1)=0,"Male","Female") -> Female | C57: =CHOOSE(RANDBETWEEN(1,4),"18-25","26-35","36-45","46+") -> 46+ | D57: 56 | E57: 38 | F57: 1 | G57: 45967 | M57: 143 | N57: 15 | O57: 4
A58: 57 | B58: =IF(RANDBETWEEN(0,1)=0,"Male","Female") -> Female | C58: =CHOOSE(RANDBETWEEN(1,4),"18-25","26-35","36-45","46+") -> 26-35 | D58: 57 | E58: 22 | F58: 7 | G58: 45857 | M58: 37 | N58: 12 | O58: 4
A59: 58 | B59: =IF(RANDBETWEEN(0,1)=0,"Male","Female") -> Male | C59: =CHOOSE(RANDBETWEEN(1,4),"18-25","26-35","36-45","46+") -> 18-25 | D59: 58 | E59: 19 | F59: 3 | G59: 45732 | M59: 120 | N59: 10 | O59: 3
A60: 59 | B60: =IF(RANDBETWEEN(0,1)=0,"Male","Female") -> Female | C60: =CHOOSE(RANDBETWEEN(1,4),"18-25","26-35","36-45","46+") -> 26-35 | D60: 59 | E60: 43 | F60: 7 | G60: 45886 | M60: 110 | N60: 24 | O60: 5
A61: 60 | B61: =IF(RANDBETWEEN(0,1)=0,"Male","Female") -> Male | C61: =CHOOSE(RANDBETWEEN(1,4),"18-25","26-35","36-45","46+") -> 36-45 | D61: 60 | E61: 95 | F61: 2 | G61: 45893 | M61: 110 | N61: 3 | O61: 2
A62: 61 | B62: =IF(RANDBETWEEN(0,1)=0,"Male","Female") -> Female | C62: =CHOOSE(RANDBETWEEN(1,4),"18-25","26-35","36-45","46+") -> 18-25 | D62: 61 | E62: 26 | F62: 2 | G62: 45710 | M62: 153 | N62: 14 | O62: 3
A63: 62 | B63: =IF(RANDBETWEEN(0,1)=0,"Male","Female") -> Female | C63: =CHOOSE(RANDBETWEEN(1,4),"18-25","26-35","36-45","46+") -> 36-45 | D63: 62 | E63: 83 | F63: 2 | G63: 45871 | M63: 121 | N63: 1 | O63: 3
... A101: 100 | B101: =IF(RANDBETWEEN(0,1)=0,"Male","Female") -> Female | C101: =CHOOSE(RANDBETWEEN(1,4),"18-25","26-35","36-45","46+") -> 26-35 | D101: 100 | E101: 90 | F101: 6 | G101: 45968 | M101: 177 | N101: 9 | O101: 1
D102: 101 | E102: 35 | F102: 9 | G102: 46002 | M102: 95 | N102: 6 | O102: 2
D103: 102 | E103: 3 | F103: 2 | G103: 45702 | M103: 149 | N103: 3 | O103: 3
D104: 103 | E104: 1 | F104: 3 | G104: 45965 | M104: 85 | N104: 8 | O104: 5
...
